<sdf version='1.11'>
  <model name='my_hexacopter'>
    <plugin
      filename="libgz-sim-sensors-system.so"
      name="gz::sim::systems::Sensors">
      <render_engine>ogre2</render_engine>
    </plugin>
    <plugin filename="libgz-sim-multicopter-motor-model-system.so" name="gz::sim::systems::MulticopterMotorModel">
      <robotNamespace>my_hexacopter</robotNamespace>
      <jointName>rotor_1-joint</jointName>
      <jointName>rotor_2-joint</jointName>
      <jointName>rotor_3-joint</jointName>
      <jointName>rotor_4-joint</jointName>
      <jointName>rotor_5-joint</jointName>
      <jointName>rotor_6-joint</jointName>
      <linkName>rotor_1_link</linkName>
      <linkName>rotor_2_link</linkName>
      <linkName>rotor_3_link</linkName>
      <linkName>rotor_4_link</linkName>
      <linkName>rotor_5_link</linkName>
      <linkName>rotor_6_link</linkName>
      <turningDirection>cw</turningDirection>
      <turningDirection>ccw</turningDirection>
      <turningDirection>cw</turningDirection>
      <turningDirection>ccw</turningDirection>
      <turningDirection>cw</turningDirection>
      <turningDirection>ccw</turningDirection>
      <motorType>velocity</motorType>
      <motorConstant>8.54858e-06</motorConstant>
      <momentConstant>0.016</momentConstant>
      <commandSubTopic>command/motor_speed</commandSubTopic>
      <motorNumber>0</motorNumber>
      <motorNumber>1</motorNumber>
      <motorNumber>2</motorNumber>
      <motorNumber>3</motorNumber>
      <motorNumber>4</motorNumber>
      <motorNumber>5</motorNumber>
      <rotorDragCoefficient>0.000806428</rotorDragCoefficient>
      <rotorVelocitySlowdownSim>10</rotorVelocitySlowdownSim>
      <frequencyCutoff>500</frequencyCutoff>
      <samplingRate>250</samplingRate>
    </plugin>
    
    <static>false</static>
    <pose>0 0 1 0 0 0</pose> 
    <link name='base_link'>
      <inertial>
        <mass>1.5</mass>
        <inertia>
          <ixx>0.03</ixx><ixy>0</ixy><ixz>0</ixz>
          <iyy>0.03</iyy><iyz>0</iyz><izz>0.06</izz>
        </inertia>
      </inertial>
      <collision name='base_link_collision'>
        <geometry><box><size>1.3 1.1 0.7</size></box></geometry>
      </collision>
      <visual name='base_link_visual'>
        <pose>0 0 0 3.14159 0 0</pose>
        <geometry>
          <mesh>
            <scale>1 1 1</scale>
            <uri>model://my_hexacopter/meshes/base_link.STL</uri>
          </mesh>
        </geometry>
        <material>
          <diffuse>1 1 1 1</diffuse>
          <ambient>1 1 1 1</ambient>
        </material>
      </visual>

      <sensor name="air_pressure_sensor" type="air_pressure">
        <always_on>1</always_on>
        <update_rate>50</update_rate>
        <air_pressure>
          <pressure>
            <noise type="gaussian"><mean>0</mean><stddev>3</stddev></noise>
          </pressure>
        </air_pressure>
      </sensor>

      <sensor name="magnetometer_sensor" type="magnetometer">
        <always_on>1</always_on>
        <update_rate>100</update_rate>
        <magnetometer>
          <x><noise type="gaussian"><stddev>0.0001</stddev></noise></x>
          <y><noise type="gaussian"><stddev>0.0001</stddev></noise></y>
          <z><noise type="gaussian"><stddev>0.0001</stddev></noise></z>
        </magnetometer>
      </sensor>

      <sensor name="imu_sensor" type="imu">
        <always_on>1</always_on>
        <update_rate>250</update_rate>
        <imu>
          <angular_velocity>
            <x><noise type="gaussian"><mean>0.0</mean><stddev>0.00087</stddev></noise></x>
            <y><noise type="gaussian"><mean>0.0</mean><stddev>0.00087</stddev></noise></y>
            <z><noise type="gaussian"><mean>0.0</mean><stddev>0.00087</stddev></noise></z>
          </angular_velocity>
          <linear_acceleration>
            <x><noise type="gaussian"><mean>0.0</mean><stddev>0.00637</stddev></noise></x>
            <y><noise type="gaussian"><mean>0.0</mean><stddev>0.00637</stddev></noise></y>
            <z><noise type="gaussian"><mean>0.0</mean><stddev>0.00686</stddev></noise></z>
          </linear_acceleration>
        </imu>
      </sensor>

      <sensor name="navsat_sensor" type="navsat">
        <always_on>1</always_on>
        <update_rate>30</update_rate>
      </sensor>
    </link>

    <joint name='rotor_1-joint' type='revolute'>
      <parent>base_link</parent>
      <child>rotor_1_link</child>
      <axis>
        <xyz>0 0 1</xyz>
        <limit><lower>-1e16</lower><upper>1e16</upper></limit>
        <dynamics><damping>0.005</damping></dynamics>
      </axis>
    </joint>
    <link name='rotor_1_link'>
      <pose>0.58964 0.00033 0.13625 0 0 0</pose>
      <inertial>
        <mass>0.05</mass>
        <inertia>
          <ixx>0.0001</ixx><ixy>0</ixy><ixz>0</ixz>
          <iyy>0.0001</iyy><iyz>0</iyz><izz>0.0002</izz>
        </inertia>
      </inertial>
      <collision name='rotor_1_link_collision'>
        <geometry><cylinder><radius>0.25</radius><length>0.01</length></cylinder></geometry>
      </collision>
      <visual name='rotor_1_link_visual'>
        <pose>0 0 0 3.14159 0 0</pose>
        <geometry><mesh><uri>model://my_hexacopter/meshes/rotor_1_link.STL</uri></mesh></geometry>
        <material><diffuse>0 0 0 1</diffuse><ambient>0 0 0 1</ambient></material>
      </visual>
    </link>

    <joint name='rotor_2-joint' type='revolute'>
      <parent>base_link</parent>
      <child>rotor_2_link</child>
      <axis>
        <xyz>0 0 1</xyz>
        <limit><lower>-1e16</lower><upper>1e16</upper></limit>
        <dynamics><damping>0.005</damping></dynamics>
      </axis>
    </joint>
    <link name='rotor_2_link'>
      <pose>-0.65761 0.00033 0.13054 0 0 0</pose>
      <inertial>
        <mass>0.05</mass>
        <inertia>
          <ixx>0.0001</ixx><ixy>0</ixy><ixz>0</ixz>
          <iyy>0.0001</iyy><iyz>0</iyz><izz>0.0002</izz>
        </inertia>
      </inertial>
      <collision name='rotor_2_link_collision'>
        <geometry><cylinder><radius>0.25</radius><length>0.01</length></cylinder></geometry>
      </collision>
      <visual name='rotor_2_link_visual'>
        <pose>0 0 0 3.14159 0 0</pose>
        <geometry><mesh><uri>model://my_hexacopter/meshes/rotor_2_link.STL</uri></mesh></geometry>
        <material><diffuse>0 0 0 1</diffuse><ambient>0 0 0 1</ambient></material>
      </visual>
    </link>

    <joint name='rotor_3-joint' type='revolute'>
      <parent>base_link</parent>
      <child>rotor_3_link</child>
      <axis>
        <xyz>0 0 1</xyz>
        <limit><lower>-1e16</lower><upper>1e16</upper></limit>
        <dynamics><damping>0.005</damping></dynamics>
      </axis>
    </joint>
    <link name='rotor_3_link'>
      <pose>-0.3458 -0.53975 0.13625 0 0 0</pose>
      <inertial>
        <mass>0.05</mass>
        <inertia>
          <ixx>0.0001</ixx><ixy>0</ixy><ixz>0</ixz>
          <iyy>0.0001</iyy><iyz>0</iyz><izz>0.0002</izz>
        </inertia>
      </inertial>
      <collision name='rotor_3_link_collision'>
        <geometry><cylinder><radius>0.25</radius><length>0.01</length></cylinder></geometry>
      </collision>
      <visual name='rotor_3_link_visual'>
        <pose>0 0 0 3.14159 0 0</pose>
        <geometry><mesh><uri>model://my_hexacopter/meshes/rotor_3_link.STL</uri></mesh></geometry>
        <material><diffuse>0 0 0 1</diffuse><ambient>0 0 0 1</ambient></material>
      </visual>
    </link>

    <joint name='rotor_4-joint' type='revolute'>
      <parent>base_link</parent>
      <child>rotor_4_link</child>
      <axis>
        <xyz>0 0 1</xyz>
        <limit><lower>-1e16</lower><upper>1e16</upper></limit>
        <dynamics><damping>0.005</damping></dynamics>
      </axis>
    </joint>
    <link name='rotor_4_link'>
      <pose>0.27782 0.54041 0.13054 0 0 0</pose>
      <inertial>
        <mass>0.05</mass>
        <inertia>
          <ixx>0.0001</ixx><ixy>0</ixy><ixz>0</ixz>
          <iyy>0.0001</iyy><iyz>0</iyz><izz>0.0002</izz>
        </inertia>
      </inertial>
      <collision name='rotor_4_link_collision'>
        <geometry><cylinder><radius>0.25</radius><length>0.01</length></cylinder></geometry>
      </collision>
      <visual name='rotor_4_link_visual'>
        <pose>0 0 0 3.14159 0 0</pose>
        <geometry><mesh><uri>model://my_hexacopter/meshes/rotor_4_link.STL</uri></mesh></geometry>
        <material><diffuse>0 0 0 1</diffuse><ambient>0 0 0 1</ambient></material>
      </visual>
    </link>

    <joint name='rotor_5-joint' type='revolute'>
      <parent>base_link</parent>
      <child>rotor_5_link</child>
      <axis>
        <xyz>0 0 1</xyz>
        <limit><lower>-1e16</lower><upper>1e16</upper></limit>
        <dynamics><damping>0.005</damping></dynamics>
      </axis>
    </joint>
    <link name='rotor_5_link'>
      <pose>0.27782 -0.53975 0.13054 0 0 0</pose>
      <inertial>
        <mass>0.05</mass>
        <inertia>
          <ixx>0.0001</ixx><ixy>0</ixy><ixz>0</ixz>
          <iyy>0.0001</iyy><iyz>0</iyz><izz>0.0002</izz>
        </inertia>
      </inertial>
      <collision name='rotor_5_link_collision'>
        <geometry><cylinder><radius>0.25</radius><length>0.01</length></cylinder></geometry>
      </collision>
      <visual name='rotor_5_link_visual'>
        <pose>0 0 0 3.14159 0 0</pose>
        <geometry><mesh><uri>model://my_hexacopter/meshes/rotor_5_link.STL</uri></mesh></geometry>
        <material><diffuse>0 0 0 1</diffuse><ambient>0 0 0 1</ambient></material>
      </visual>
    </link>

    <joint name='rotor_6-joint' type='revolute'>
      <parent>base_link</parent>
      <child>rotor_6_link</child>
      <axis>
        <xyz>0 0 1</xyz>
        <limit><lower>-1e16</lower><upper>1e16</upper></limit>
        <dynamics><damping>0.005</damping></dynamics>
      </axis>
    </joint>
    <link name='rotor_6_link'>
      <pose>-0.3458 0.53975 0.13625 0 0 0</pose>
      <inertial>
        <mass>0.05</mass>
        <inertia>
          <ixx>0.0001</ixx><ixy>0</ixy><ixz>0</ixz>
          <iyy>0.0001</iyy><iyz>0</iyz><izz>0.0002</izz>
        </inertia>
      </inertial>
      <collision name='rotor_6_link_collision'>
        <geometry><cylinder><radius>0.25</radius><length>0.01</length></cylinder></geometry>
      </collision>
      <visual name='rotor_6_link_visual'>
        <pose>0 0 0 3.14159 0 0</pose>
        <geometry><mesh><uri>model://my_hexacopter/meshes/rotor_6_link.STL</uri></mesh></geometry>
        <material><diffuse>0 0 0 1</diffuse><ambient>0 0 0 1</ambient></material>
      </visual>
    </link>
  </model>
</sdf>
